<?xml version="1.0" ?>
<!-- =================================================================================== -->
<!-- |    This document was autogenerated by xacro from gueladan.urdf.xacro            | -->
<!-- |    EDITING THIS FILE BY HAND IS NOT RECOMMENDED                                 | -->
<!-- =================================================================================== -->
<robot name="GUELADAN">
  <!-- Specify some standard inertial calculations https://en.wikipedia.org/wiki/List_of_moments_of_inertia -->
  <!-- These make use of xacro's mathematical functionality -->
  <material name="blue">
    <color rgba="0 0 0.8 1"/>
  </material>
  <material name="black">
    <color rgba="0 0 0 1"/>
  </material>
  <material name="white">
    <color rgba="1 1 1 1"/>
  </material>
  <link name="base_link"/>
  <joint name="base_join" type="fixed">
    <parent link="base_link"/>
    <child link="chassis_link_back"/>
    <origin rpy="0 0 0" xyz="-0.325 0 0"/>
  </joint>
  <link name="chassis_link_back">
    <visual>
      <geometry>
        <box size="0.06 0.6 0.04"/>
      </geometry>
      <origin rpy="0 0 0" xyz="0 0 0"/>
      <material name="white"/>
    </visual>
    <collision>
      <geometry>
        <box size="0.06 0.6 0.04"/>
      </geometry>
      <origin rpy="0 0 0" xyz="0 0 0"/>
    </collision>
    <inertial>
      <origin rpy="0 0 0" xyz="0 0 0"/>
      <mass value="1.8"/>
      <inertia ixx="0.05424" ixy="0.0" ixz="0.0" iyy="0.00078" iyz="0.0" izz="0.05454"/>
    </inertial>
  </link>
  <joint name="base_link_right_joint" type="fixed">
    <parent link="base_link"/>
    <child link="chassis_link_right"/>
    <origin rpy="0 0 0" xyz="0 -0.27 0"/>
  </joint>
  <joint name="base_link_left_joint" type="fixed">
    <parent link="base_link"/>
    <child link="chassis_link_left"/>
    <origin rpy="0 0 0" xyz="0 0.27 0"/>
  </joint>
  <link name="chassis_link_right">
    <visual>
      <geometry>
        <box size="0.71 0.06 0.04"/>
      </geometry>
      <origin rpy="0 0 0" xyz="0 0 0"/>
      <material name="white"/>
    </visual>
    <collision>
      <geometry>
        <box size="0.71 0.06 0.04"/>
      </geometry>
      <origin rpy="0 0 0" xyz="0 0 0"/>
      <material name="white"/>
    </collision>
    <inertial>
      <origin rpy="0 0 0" xyz="0 0 0"/>
      <mass value="2.13"/>
      <inertia ixx="0.0009229999999999999" ixy="0.0" ixz="0.0" iyy="0.08976175" iyz="0.0" izz="0.09011675000000001"/>
    </inertial>
  </link>
  <link name="chassis_link_left">
    <visual>
      <geometry>
        <box size="0.71 0.06 0.04"/>
      </geometry>
      <origin rpy="0 0 0" xyz="0 0 0"/>
      <material name="blue"/>
    </visual>
    <collision>
      <geometry>
        <box size="0.71 0.06 0.04"/>
      </geometry>
      <origin rpy="0 0 0" xyz="0 0 0"/>
      <material name="blue"/>
    </collision>
    <inertial>
      <origin rpy="0 0 0" xyz="0 0 0"/>
      <mass value="2.13"/>
      <inertia ixx="0.029039000000000002" ixy="0.0" ixz="0.0" iyy="0.11787775" iyz="0.0" izz="0.09011675000000001"/>
    </inertial>
  </link>
  <joint name="base_link_right_oblic_joint" type="fixed">
    <parent link="base_link"/>
    <child link="chassis_link_right_oblic"/>
    <origin rpy="0 0 -2.11" xyz="0.375 -0.21 0"/>
  </joint>
  <joint name="base_link_left_oblic_joint" type="fixed">
    <parent link="base_link"/>
    <child link="chassis_link_left_oblic"/>
    <origin rpy="0 0 2.11" xyz="0.375 0.21 0"/>
  </joint>
  <joint name="base_link_front_joint" type="fixed">
    <parent link="base_link"/>
    <child link="chassis_link_front"/>
    <origin rpy="0 0 0" xyz="0.415 0 0"/>
  </joint>
  <joint name="chassis_link_2_joint" type="fixed">
    <parent link="base_link"/>
    <child link="chassis_link_2"/>
    <origin rpy="0 0 0" xyz="0.2254 0 0"/>
  </joint>
  <joint name="chassis_link_1_joint" type="fixed">
    <parent link="base_link"/>
    <child link="chassis_link_1"/>
    <origin rpy="0 0 0" xyz="-0.1346 0 0"/>
  </joint>
  <link name="chassis_link_left_oblic">
    <visual>
      <geometry>
        <box size="0.175 0.06 0.04"/>
      </geometry>
      <origin rpy="0 0 0" xyz="0 0 0"/>
      <material name="blue"/>
    </visual>
    <collision>
      <geometry>
        <box size="0.175 0.06 0.04"/>
      </geometry>
      <origin rpy="0 0 0" xyz="0 0 0"/>
      <material name="blue"/>
    </collision>
    <inertial>
      <origin rpy="0 0 0" xyz="0 0 0"/>
      <mass value="0.525"/>
      <inertia ixx="0.00022749999999999997" ixy="0.0" ixz="0.0" iyy="0.0014098437499999999" iyz="0.0" izz="0.0014973437499999998"/>
    </inertial>
  </link>
  <link name="chassis_link_right_oblic">
    <visual>
      <geometry>
        <box size="0.175 0.06 0.04"/>
      </geometry>
      <origin rpy="0 0 0" xyz="0 0 0"/>
      <material name="white"/>
    </visual>
    <collision>
      <geometry>
        <box size="0.175 0.06 0.04"/>
      </geometry>
      <origin rpy="0 0 0" xyz="0 0 0"/>
      <material name="white"/>
    </collision>
    <inertial>
      <origin rpy="0 0 0" xyz="0 0 0"/>
      <mass value="0.525"/>
      <inertia ixx="0.007157500000000001" ixy="0.0" ixz="0.0" iyy="0.008339843750000001" iyz="0.0" izz="0.0014973437499999998"/>
    </inertial>
  </link>
  <link name="chassis_link_front">
    <visual>
      <geometry>
        <box size="0.06 0.3 0.04"/>
      </geometry>
      <origin rpy="0 0 0" xyz="0 0 0"/>
      <material name="white"/>
    </visual>
    <collision>
      <geometry>
        <box size="0.06 0.3 0.04"/>
      </geometry>
      <origin rpy="0 0 0" xyz="0 0 0"/>
      <material name="white"/>
    </collision>
    <inertial>
      <origin rpy="0 0 0" xyz="0 0 0"/>
      <mass value="0.9"/>
      <inertia ixx="0.00687" ixy="0.0" ixz="0.0" iyy="0.00039" iyz="0.0" izz="0.00702"/>
    </inertial>
  </link>
  <link name="chassis_link_1">
    <visual>
      <geometry>
        <box size="0.06 0.48 0.04"/>
      </geometry>
      <origin rpy="0 0 0" xyz="0 0 0"/>
      <material name="white"/>
    </visual>
    <collision>
      <geometry>
        <box size="0.06 0.48 0.04"/>
      </geometry>
      <origin rpy="0 0 0" xyz="0 0 0"/>
      <material name="white"/>
    </collision>
    <inertial>
      <origin rpy="0 0 0" xyz="0 0 0"/>
      <mass value="0.9"/>
      <inertia ixx="0.00687" ixy="0.0" ixz="0.0" iyy="0.00039" iyz="0.0" izz="0.00702"/>
    </inertial>
  </link>
  <link name="chassis_link_2">
    <visual>
      <geometry>
        <box size="0.06 0.48 0.04"/>
      </geometry>
      <origin rpy="0 0 0" xyz="0 0 0"/>
      <material name="white"/>
    </visual>
    <collision>
      <geometry>
        <box size="0.06 0.48 0.04"/>
      </geometry>
      <origin rpy="0 0 0" xyz="0 0 0"/>
      <material name="white"/>
    </collision>
    <inertial>
      <origin rpy="0 0 0" xyz="0 0 0"/>
      <mass value="0.9"/>
      <inertia ixx="0.00687" ixy="0.0" ixz="0.0" iyy="0.00039" iyz="0.0" izz="0.00702"/>
    </inertial>
  </link>
  <link name="back_left_wheel">
    <visual>
      <geometry>
        <cylinder length="0.08" radius="0.1"/>
      </geometry>
      <origin rpy="0 0 0" xyz="0 0 0"/>
      <material name="black"/>
    </visual>
    <collision>
      <geometry>
        <cylinder length="0.08" radius="0.1"/>
      </geometry>
      <origin rpy="0 0 0" xyz="0 0 0"/>
      <material name="black"/>
    </collision>
    <inertial>
      <origin rpy="0 0 0" xyz="0 0 0"/>
      <mass value="0.5"/>
      <inertia ixx="0.00027916666666666666" ixy="0.0" ixz="0.0" iyy="0.00027916666666666666" iyz="0.0" izz="2.5e-05"/>
    </inertial>
  </link>
  <link name="front_left_wheel">
    <visual>
      <geometry>
        <cylinder length="0.08" radius="0.1"/>
      </geometry>
      <origin rpy="0 0 0" xyz="0 0 0"/>
      <material name="black"/>
    </visual>
    <collision>
      <geometry>
        <cylinder length="0.08" radius="0.1"/>
      </geometry>
      <origin rpy="0 0 0" xyz="0 0 0"/>
      <material name="black"/>
    </collision>
    <inertial>
      <origin rpy="0 0 0" xyz="0 0 0"/>
      <mass value="0.5"/>
      <inertia ixx="0.00027916666666666666" ixy="0.0" ixz="0.0" iyy="0.00027916666666666666" iyz="0.0" izz="2.5e-05"/>
    </inertial>
  </link>
  <link name="back_right_wheel">
    <visual>
      <geometry>
        <cylinder length="0.08" radius="0.1"/>
      </geometry>
      <origin rpy="0 0 0" xyz="0 0 0"/>
      <material name="blue"/>
    </visual>
    <collision>
      <geometry>
        <cylinder length="0.08" radius="0.1"/>
      </geometry>
      <origin rpy="0 0 0" xyz="0 0 0"/>
      <material name="blue"/>
    </collision>
    <inertial>
      <origin rpy="0 0 0" xyz="0 0 0"/>
      <mass value="0.5"/>
      <inertia ixx="0.00027916666666666666" ixy="0.0" ixz="0.0" iyy="0.00027916666666666666" iyz="0.0" izz="2.5e-05"/>
    </inertial>
  </link>
  <link name="front_right_wheel">
    <visual>
      <geometry>
        <cylinder length="0.08" radius="0.1"/>
      </geometry>
      <origin rpy="0 0 0" xyz="0 0 0"/>
      <material name="blue"/>
    </visual>
    <collision>
      <geometry>
        <cylinder length="0.08" radius="0.1"/>
      </geometry>
      <origin rpy="0 0 0" xyz="0 0 0"/>
      <material name="blue"/>
    </collision>
    <inertial>
      <origin rpy="0 0 0" xyz="0 0 0"/>
      <mass value="0.5"/>
      <inertia ixx="0.00027916666666666666" ixy="0.0" ixz="0.0" iyy="0.00027916666666666666" iyz="0.0" izz="2.5e-05"/>
    </inertial>
  </link>
  <joint name="front_right_wheel_joint" type="continuous">
    <parent link="base_link"/>
    <child link="front_right_wheel"/>
    <origin rpy="1.57 0 0" xyz="0.2254 -0.35 -0.03"/>
    <axis xyz="0 0 -1"/>
  </joint>
  <transmission name="front_right_wheel_trans">
    <type>transmission_interface/SimpleTransmission</type>
    <actuator name="front_right_wheel_motor">
      <mechanicalReduction>1</mechanicalReduction>
    </actuator>
    <joint name="front_right_wheel_joint">
      <hardwareInterface>hardware_interface/VelocityJointInterface</hardwareInterface>
    </joint>
  </transmission>
  <joint name="back_right_wheel_joint" type="continuous">
    <parent link="base_link"/>
    <child link="back_right_wheel"/>
    <origin rpy="1.57 0 0" xyz="-0.1346 -0.35 -0.03"/>
    <axis xyz="0 0 -1"/>
  </joint>
  <transmission name="back_right_wheel_trans">
    <type>transmission_interface/SimpleTransmission</type>
    <actuator name="back_right_wheel_motor">
      <mechanicalReduction>1</mechanicalReduction>
    </actuator>
    <joint name="back_right_wheel_joint">
      <hardwareInterface>hardware_interface/VelocityJointInterface</hardwareInterface>
    </joint>
  </transmission>
  <joint name="front_left_wheel_joint" type="continuous">
    <parent link="base_link"/>
    <child link="front_left_wheel"/>
    <origin rpy="-1.57 0 0" xyz="0.2254 0.35 -0.03"/>
    <axis xyz="0 0 1"/>
  </joint>
  <transmission name="front_left_wheel_trans">
    <type>transmission_interface/SimpleTransmission</type>
    <actuator name="front_left_wheel_motor">
      <mechanicalReduction>1</mechanicalReduction>
    </actuator>
    <joint name="front_left_wheel_joint">
      <hardwareInterface>hardware_interface/VelocityJointInterface</hardwareInterface>
    </joint>
  </transmission>
  <joint name="back_left_wheel_joint" type="continuous">
    <parent link="base_link"/>
    <child link="back_left_wheel"/>
    <origin rpy="-1.57 0 0" xyz="-0.1346 0.35 -0.03"/>
    <axis xyz="0 0 1"/>
  </joint>
  <transmission name="back_left_wheel_trans">
    <type>transmission_interface/SimpleTransmission</type>
    <actuator name="back_left_wheel_motor">
      <mechanicalReduction>1</mechanicalReduction>
    </actuator>
    <joint name="back_left_wheel_joint">
      <hardwareInterface>hardware_interface/VelocityJointInterface</hardwareInterface>
    </joint>
  </transmission>
  <gazebo reference="back_right_wheel">
    <mu1 value="200.0"/>
    <mu2 value="100.0"/>
    <kp value="10000000.0"/>
    <kd value="1.0"/>
    <material>Gazebo/Grey</material>
  </gazebo>
  <gazebo reference="front_right_wheel">
    <mu1 value="200.0"/>
    <mu2 value="100.0"/>
    <kp value="10000000.0"/>
    <kd value="1.0"/>
    <material>Gazebo/Grey</material>
  </gazebo>
  <gazebo reference="front_left_wheel">
    <mu1 value="200.0"/>
    <mu2 value="100.0"/>
    <kp value="10000000.0"/>
    <kd value="1.0"/>
    <material>Gazebo/Grey</material>
  </gazebo>
  <gazebo reference="back_left_wheel">
    <mu1 value="200.0"/>
    <mu2 value="100.0"/>
    <kp value="10000000.0"/>
    <kd value="1.0"/>
    <material>Gazebo/Grey</material>
  </gazebo>
  <!-- Specify some standard inertial calculations https://en.wikipedia.org/wiki/List_of_moments_of_inertia -->
  <!-- These make use of xacro's mathematical functionality -->
  <joint name="base_top_join" type="fixed">
    <parent link="base_link"/>
    <child link="base_link_top"/>
    <origin rpy="0 0 0" xyz="0 0 0.35"/>
  </joint>
  <link name="base_link_top"/>
  <joint name="base_chassis_top_join" type="fixed">
    <parent link="base_link_top"/>
    <child link="chassis_top_link_back"/>
    <origin rpy="0 0 0" xyz="-0.325 0 0"/>
  </joint>
  <link name="chassis_top_link_back">
    <visual>
      <geometry>
        <box size="0.06 0.6 0.04"/>
      </geometry>
      <origin rpy="0 0 0" xyz="0 0 0"/>
      <material name="white"/>
    </visual>
    <collision>
      <geometry>
        <box size="0.06 0.6 0.04"/>
      </geometry>
      <origin rpy="0 0 0" xyz="0 0 0"/>
    </collision>
    <inertial>
      <origin rpy="0 0 0" xyz="0 0 0"/>
      <mass value="1.8"/>
      <inertia ixx="0.05424" ixy="0.0" ixz="0.0" iyy="0.00078" iyz="0.0" izz="0.05454"/>
    </inertial>
  </link>
  <joint name="base_link_top_right_joint" type="fixed">
    <parent link="base_link_top"/>
    <child link="chassis_top_link_right"/>
    <origin rpy="0 0 0" xyz="0 -0.27 0"/>
  </joint>
  <joint name="base_link_top_left_joint" type="fixed">
    <parent link="base_link_top"/>
    <child link="chassis_top_link_left"/>
    <origin rpy="0 0 0" xyz="0 0.27 0"/>
  </joint>
  <link name="chassis_top_link_right">
    <visual>
      <geometry>
        <box size="0.71 0.06 0.04"/>
      </geometry>
      <origin rpy="0 0 0" xyz="0 0 0"/>
      <material name="white"/>
    </visual>
    <collision>
      <geometry>
        <box size="0.71 0.06 0.04"/>
      </geometry>
      <origin rpy="0 0 0" xyz="0 0 0"/>
      <material name="white"/>
    </collision>
    <inertial>
      <origin rpy="0 0 0" xyz="0 0 0"/>
      <mass value="2.13"/>
      <inertia ixx="0.0009229999999999999" ixy="0.0" ixz="0.0" iyy="0.08976175" iyz="0.0" izz="0.09011675000000001"/>
    </inertial>
  </link>
  <link name="chassis_top_link_left">
    <visual>
      <geometry>
        <box size="0.71 0.06 0.04"/>
      </geometry>
      <origin rpy="0 0 0" xyz="0 0 0"/>
      <material name="blue"/>
    </visual>
    <collision>
      <geometry>
        <box size="0.71 0.06 0.04"/>
      </geometry>
      <origin rpy="0 0 0" xyz="0 0 0"/>
      <material name="blue"/>
    </collision>
    <inertial>
      <origin rpy="0 0 0" xyz="0 0 0"/>
      <mass value="2.13"/>
      <inertia ixx="0.029039000000000002" ixy="0.0" ixz="0.0" iyy="0.11787775" iyz="0.0" izz="0.09011675000000001"/>
    </inertial>
  </link>
  <joint name="base_link_top_right_oblic_joint" type="fixed">
    <parent link="base_link_top"/>
    <child link="chassis_top_link_right_oblic"/>
    <origin rpy="0 0 -2.11" xyz="0.375 -0.21 0"/>
  </joint>
  <joint name="base_link_top_left_oblic_joint" type="fixed">
    <parent link="base_link_top"/>
    <child link="chassis_top_link_left_oblic"/>
    <origin rpy="0 0 2.11" xyz="0.375 0.21 0"/>
  </joint>
  <joint name="base_link_top_front_joint" type="fixed">
    <parent link="base_link_top"/>
    <child link="chassis_top_link_front"/>
    <origin rpy="0 0 0" xyz="0.415 0 0"/>
  </joint>
  <joint name="chassis_top_link_2_joint" type="fixed">
    <parent link="base_link_top"/>
    <child link="chassis_top_link_2"/>
    <origin rpy="0 0 0" xyz="0.2254 0 0"/>
  </joint>
  <joint name="chassis_top_link_1_joint" type="fixed">
    <parent link="base_link_top"/>
    <child link="chassis_top_link_1"/>
    <origin rpy="0 0 0" xyz="-0.1346 0 0"/>
  </joint>
  <link name="chassis_top_link_left_oblic">
    <visual>
      <geometry>
        <box size="0.175 0.06 0.04"/>
      </geometry>
      <origin rpy="0 0 0" xyz="0 0 0"/>
      <material name="blue"/>
    </visual>
    <collision>
      <geometry>
        <box size="0.175 0.06 0.04"/>
      </geometry>
      <origin rpy="0 0 0" xyz="0 0 0"/>
      <material name="blue"/>
    </collision>
    <inertial>
      <origin rpy="0 0 0" xyz="0 0 0"/>
      <mass value="0.525"/>
      <inertia ixx="0.00022749999999999997" ixy="0.0" ixz="0.0" iyy="0.0014098437499999999" iyz="0.0" izz="0.0014973437499999998"/>
    </inertial>
  </link>
  <link name="chassis_top_link_right_oblic">
    <visual>
      <geometry>
        <box size="0.175 0.06 0.04"/>
      </geometry>
      <origin rpy="0 0 0" xyz="0 0 0"/>
      <material name="white"/>
    </visual>
    <collision>
      <geometry>
        <box size="0.175 0.06 0.04"/>
      </geometry>
      <origin rpy="0 0 0" xyz="0 0 0"/>
      <material name="white"/>
    </collision>
    <inertial>
      <origin rpy="0 0 0" xyz="0 0 0"/>
      <mass value="0.525"/>
      <inertia ixx="0.007157500000000001" ixy="0.0" ixz="0.0" iyy="0.008339843750000001" iyz="0.0" izz="0.0014973437499999998"/>
    </inertial>
  </link>
  <link name="chassis_top_link_front">
    <visual>
      <geometry>
        <box size="0.06 0.3 0.04"/>
      </geometry>
      <origin rpy="0 0 0" xyz="0 0 0"/>
      <material name="white"/>
    </visual>
    <collision>
      <geometry>
        <box size="0.06 0.3 0.04"/>
      </geometry>
      <origin rpy="0 0 0" xyz="0 0 0"/>
      <material name="white"/>
    </collision>
    <inertial>
      <origin rpy="0 0 0" xyz="0 0 0"/>
      <mass value="0.9"/>
      <inertia ixx="0.00687" ixy="0.0" ixz="0.0" iyy="0.00039" iyz="0.0" izz="0.00702"/>
    </inertial>
  </link>
  <link name="chassis_top_link_1">
    <visual>
      <geometry>
        <box size="0.06 0.48 0.04"/>
      </geometry>
      <origin rpy="0 0 0" xyz="0 0 0"/>
      <material name="white"/>
    </visual>
    <collision>
      <geometry>
        <box size="0.06 0.48 0.04"/>
      </geometry>
      <origin rpy="0 0 0" xyz="0 0 0"/>
      <material name="white"/>
    </collision>
    <inertial>
      <origin rpy="0 0 0" xyz="0 0 0"/>
      <mass value="0.9"/>
      <inertia ixx="0.00687" ixy="0.0" ixz="0.0" iyy="0.00039" iyz="0.0" izz="0.00702"/>
    </inertial>
  </link>
  <link name="chassis_top_link_2">
    <visual>
      <geometry>
        <box size="0.06 0.48 0.04"/>
      </geometry>
      <origin rpy="0 0 0" xyz="0 0 0"/>
      <material name="white"/>
    </visual>
    <collision>
      <geometry>
        <box size="0.06 0.48 0.04"/>
      </geometry>
      <origin rpy="0 0 0" xyz="0 0 0"/>
      <material name="white"/>
    </collision>
    <inertial>
      <origin rpy="0 0 0" xyz="0 0 0"/>
      <mass value="0.9"/>
      <inertia ixx="0.00687" ixy="0.0" ixz="0.0" iyy="0.00039" iyz="0.0" izz="0.00702"/>
    </inertial>
  </link>
  <gazebo>
    <plugin filename="libgazebo_ros_control.so" name="gazebo_ros_control">
      <robotNamespace>/</robotNamespace>
    </plugin>
  </gazebo>
  <!-- Specify some standard inertial calculations https://en.wikipedia.org/wiki/List_of_moments_of_inertia -->
  <!-- These make use of xacro's mathematical functionality -->
  <joint name="base_bar_join" type="fixed">
    <parent link="base_link"/>
    <child link="base_bar_link"/>
    <origin rpy="0 0 0" xyz="0 0 0.175"/>
  </joint>
  <link name="base_bar_link"/>
  <joint name="base_chassis_bar_front_left_joint" type="fixed">
    <parent link="base_bar_link"/>
    <child link="base_chassis_bar_front_left"/>
    <origin rpy="0 0 0" xyz="0.415 0.13 0"/>
  </joint>
  <link name="base_chassis_bar_front_left">
    <visual>
      <geometry>
        <box size="0.06 0.04 0.31"/>
      </geometry>
      <origin rpy="0 0 0" xyz="0 0 0"/>
      <material name="white"/>
    </visual>
    <collision>
      <geometry>
        <box size="0.06 0.04 0.31"/>
      </geometry>
      <origin rpy="0 0 0" xyz="0 0 0"/>
    </collision>
    <inertial>
      <origin rpy="0 0 0" xyz="0 0 0"/>
      <mass value="0.93"/>
      <inertia ixx="0.00757175" ixy="0.0" ixz="0.0" iyy="0.007726750000000001" iyz="0.0" izz="0.000403"/>
    </inertial>
  </link>
  <joint name="base_chassis_bar_front_right_joint" type="fixed">
    <parent link="base_bar_link"/>
    <child link="base_chassis_bar_front_right"/>
    <origin rpy="0 0 0" xyz="0.415 -0.13 0"/>
  </joint>
  <link name="base_chassis_bar_front_right">
    <visual>
      <geometry>
        <box size="0.06 0.04 0.31"/>
      </geometry>
      <origin rpy="0 0 0" xyz="0 0 0"/>
      <material name="white"/>
    </visual>
    <collision>
      <geometry>
        <box size="0.06 0.04 0.31"/>
      </geometry>
      <origin rpy="0 0 0" xyz="0 0 0"/>
    </collision>
    <inertial>
      <origin rpy="0 0 0" xyz="0 0 0"/>
      <mass value="0.93"/>
      <inertia ixx="0.00757175" ixy="0.0" ixz="0.0" iyy="0.007726750000000001" iyz="0.0" izz="0.000403"/>
    </inertial>
  </link>
  <joint name="base_chassis_bar_back_2_left_joint" type="fixed">
    <parent link="base_bar_link"/>
    <child link="base_chassis_bar_back_2_left"/>
    <origin rpy="0 0 0" xyz="0.2254 0.28 0"/>
  </joint>
  <link name="base_chassis_bar_back_2_left">
    <visual>
      <geometry>
        <box size="0.06 0.04 0.31"/>
      </geometry>
      <origin rpy="0 0 0" xyz="0 0 0"/>
      <material name="white"/>
    </visual>
    <collision>
      <geometry>
        <box size="0.06 0.04 0.31"/>
      </geometry>
      <origin rpy="0 0 0" xyz="0 0 0"/>
    </collision>
    <inertial>
      <origin rpy="0 0 0" xyz="0 0 0"/>
      <mass value="0.93"/>
      <inertia ixx="0.00757175" ixy="0.0" ixz="0.0" iyy="0.007726750000000001" iyz="0.0" izz="0.000403"/>
    </inertial>
  </link>
  <joint name="base_chassis_bar_back_2_right_joint" type="fixed">
    <parent link="base_bar_link"/>
    <child link="base_chassis_bar_back_2_right"/>
    <origin rpy="0 0 0" xyz="0.2254 -0.28 0"/>
  </joint>
  <link name="base_chassis_bar_back_2_right">
    <visual>
      <geometry>
        <box size="0.06 0.04 0.31"/>
      </geometry>
      <origin rpy="0 0 0" xyz="0 0 0"/>
      <material name="white"/>
    </visual>
    <collision>
      <geometry>
        <box size="0.06 0.04 0.31"/>
      </geometry>
      <origin rpy="0 0 0" xyz="0 0 0"/>
    </collision>
    <inertial>
      <origin rpy="0 0 0" xyz="0 0 0"/>
      <mass value="0.93"/>
      <inertia ixx="0.00757175" ixy="0.0" ixz="0.0" iyy="0.007726750000000001" iyz="0.0" izz="0.000403"/>
    </inertial>
  </link>
  <joint name="base_chassis_bar_back_1_left_joint" type="fixed">
    <parent link="base_bar_link"/>
    <child link="base_chassis_bar_back_1_left"/>
    <origin rpy="0 0 0" xyz="-0.1346 0.28 0"/>
  </joint>
  <link name="base_chassis_bar_back_1_left">
    <visual>
      <geometry>
        <box size="0.06 0.04 0.31"/>
      </geometry>
      <origin rpy="0 0 0" xyz="0 0 0"/>
      <material name="white"/>
    </visual>
    <collision>
      <geometry>
        <box size="0.06 0.04 0.31"/>
      </geometry>
      <origin rpy="0 0 0" xyz="0 0 0"/>
    </collision>
    <inertial>
      <origin rpy="0 0 0" xyz="0 0 0"/>
      <mass value="0.93"/>
      <inertia ixx="0.00757175" ixy="0.0" ixz="0.0" iyy="0.007726750000000001" iyz="0.0" izz="0.000403"/>
    </inertial>
  </link>
  <joint name="base_chassis_bar_back_1_right_joint" type="fixed">
    <parent link="base_bar_link"/>
    <child link="base_chassis_bar_back_1_right"/>
    <origin rpy="0 0 0" xyz="-0.1346 -0.28 0"/>
  </joint>
  <link name="base_chassis_bar_back_1_right">
    <visual>
      <geometry>
        <box size="0.06 0.04 0.31"/>
      </geometry>
      <origin rpy="0 0 0" xyz="0 0 0"/>
      <material name="white"/>
    </visual>
    <collision>
      <geometry>
        <box size="0.06 0.04 0.31"/>
      </geometry>
      <origin rpy="0 0 0" xyz="0 0 0"/>
    </collision>
    <inertial>
      <origin rpy="0 0 0" xyz="0 0 0"/>
      <mass value="0.93"/>
      <inertia ixx="0.00757175" ixy="0.0" ixz="0.0" iyy="0.007726750000000001" iyz="0.0" izz="0.000403"/>
    </inertial>
  </link>
  <joint name="base_chassis_bar_back_left_joint" type="fixed">
    <parent link="base_bar_link"/>
    <child link="base_chassis_bar_back_left"/>
    <origin rpy="0 0 0" xyz="-0.325 0.28 0"/>
  </joint>
  <link name="base_chassis_bar_back_left">
    <visual>
      <geometry>
        <box size="0.06 0.04 0.31"/>
      </geometry>
      <origin rpy="0 0 0" xyz="0 0 0"/>
      <material name="white"/>
    </visual>
    <collision>
      <geometry>
        <box size="0.06 0.04 0.31"/>
      </geometry>
      <origin rpy="0 0 0" xyz="0 0 0"/>
    </collision>
    <inertial>
      <origin rpy="0 0 0" xyz="0 0 0"/>
      <mass value="0.93"/>
      <inertia ixx="0.00757175" ixy="0.0" ixz="0.0" iyy="0.007726750000000001" iyz="0.0" izz="0.000403"/>
    </inertial>
  </link>
  <joint name="base_chassis_bar_back_right_joint" type="fixed">
    <parent link="base_bar_link"/>
    <child link="base_chassis_bar_back_right"/>
    <origin rpy="0 0 0" xyz="-0.325 -0.28 0"/>
  </joint>
  <link name="base_chassis_bar_back_right">
    <visual>
      <geometry>
        <box size="0.06 0.04 0.31"/>
      </geometry>
      <origin rpy="0 0 0" xyz="0 0 0"/>
      <material name="white"/>
    </visual>
    <collision>
      <geometry>
        <box size="0.06 0.04 0.31"/>
      </geometry>
      <origin rpy="0 0 0" xyz="0 0 0"/>
    </collision>
    <inertial>
      <origin rpy="0 0 0" xyz="0 0 0"/>
      <mass value="0.93"/>
      <inertia ixx="0.00757175" ixy="0.0" ixz="0.0" iyy="0.007726750000000001" iyz="0.0" izz="0.000403"/>
    </inertial>
  </link>
  <gazebo>
    <plugin filename="libgazebo_ros_control.so" name="gazebo_ros_control">
      <robotNamespace>/</robotNamespace>
    </plugin>
  </gazebo>
</robot>

