<?xml version="1.0"?>
<robot xmlns:xacro="http://www.ros.org/wiki/xacro" name="gueladan">

    <xacro:include filename="inertial_macros.xacro"/>
    <xacro:include filename="lidar.xacro" />
    <xacro:include filename="camera.xacro" />

    <material name="blue">
        <color rgba="0 0 0.8 1"/>
    </material>
    <material name="black">
        <color rgba="0 0 0 1"/>
    </material>
    <material name="white">
        <color rgba="1 1 1 1"/>
    </material>

    <link name="base_link"></link>

    <joint name="base_chassis_join" type="fixed">
        <parent link="base_link"/>
        <child link="chassis_link"/>
        <origin rpy="0 0 0" xyz="0 0 0"/>
    </joint>
    
    <link name="chassis_link">
        <visual>
        <geometry>
            <!-- <box size="0.8 0.6 0.4"/> -->
            <mesh filename="package://robot_description/meshes/chassis.stl" scale="0.001 0.001 0.001"/>
        </geometry>
        <origin rpy="0 0 1.57" xyz="0 0 0"/>
        <material name="white"/>
        </visual>
        <collision>
            <geometry>
                <box size="0.8 0.6 0.4"/>
            </geometry>
            <origin rpy="0 0 0" xyz="0 0 0.2"/>
        </collision>
        <xacro:inertial_box mass="10" x="0.8" y="0.6" z="0.4">
        <origin rpy="0 0 0" xyz="0 0 0.2"/>
        </xacro:inertial_box>
    </link>
  
  
    <link name="back_left_wheel">
        <visual>
            <geometry>
                <!-- <cylinder length="0.08" radius="0.1"/> -->
                <mesh filename="package://robot_description/meshes/wheel.stl" scale="0.001 0.001 0.001"/>
            </geometry>
            <origin rpy="0 -1.57 0" xyz="0 0 0"/>
            <material name="black"/>
        </visual>

        <collision>
            <geometry>
                <cylinder length="0.08" radius="0.1"/>
            </geometry>
            <origin rpy="0 0 0" xyz="0 0 0"/>
            <material name="black"/>
        </collision>

        <xacro:inertial_cylinder mass="0.5" length="0.08" radius="0.01">
            <origin xyz="0 0 0" rpy="0 0 0"/>
        </xacro:inertial_cylinder>
    </link>

    <link name="front_left_wheel">
        <visual>
            <geometry>
                <!-- <cylinder length="0.08" radius="0.1"/> -->
                <mesh filename="package://robot_description/meshes/wheel.stl" scale="0.001 0.001 0.001"/>
            </geometry>
            <origin rpy="0 -1.57 0" xyz="0 0 0"/>
            <material name="black"/>
        </visual>
        <collision>
            <geometry>
                <cylinder length="0.08" radius="0.1"/>
            </geometry>
            <origin rpy="0 0 0" xyz="0 0 0"/>
            <material name="black"/>
        </collision>
        <xacro:inertial_cylinder mass="0.5" length="0.08" radius="0.01">
            <origin xyz="0 0 0" rpy="0 0 0"/>
        </xacro:inertial_cylinder>
    </link>

    <link name="back_right_wheel">
        <visual>
            <geometry>
                <!-- <cylinder length="0.08" radius="0.1"/> -->
                <mesh filename="package://robot_description/meshes/wheel.stl" scale="0.001 0.001 0.001"/>
            </geometry>
            <origin rpy="0 -1.57 0" xyz="0 0 0"/>
            <material name="black"/>
        </visual>
        <collision>
            <geometry>
                <cylinder length="0.08" radius="0.1"/>
            </geometry>
            <origin rpy="0 0 0" xyz="0 0 0"/>
            <material name="black"/>
        </collision>
        <xacro:inertial_cylinder mass="0.5" length="0.08" radius="0.01">
            <origin xyz="0 0 0" rpy="0 0 0"/>
        </xacro:inertial_cylinder>
    </link>

    <link name="front_right_wheel">
        <visual>
            <geometry>
                <!-- <cylinder length="0.08" radius="0.1"/> -->
                <mesh filename="package://robot_description/meshes/wheel.stl" scale="0.001 0.001 0.001"/>
            </geometry>
            <origin rpy="0 -1.57 0" xyz="0 0 0"/>
            <material name="black"/>
        </visual>
        <collision>
            <geometry>
            <cylinder length="0.08" radius="0.1"/>
            </geometry>
            <origin rpy="0 0 0" xyz="0 0 0"/>
            <material name="black"/>
        </collision>
        <xacro:inertial_cylinder mass="0.5" length="0.08" radius="0.01">
            <origin xyz="0 0 0" rpy="0 0 0"/>
        </xacro:inertial_cylinder>
    </link>

    <joint name="front_right_wheel_joint" type="continuous">
        <parent link="base_link"/>
        <child link="front_right_wheel"/>
        <origin rpy="1.57 0 0" xyz="0.18 -0.31 0"/>
        <axis xyz="0 0 -1"/>
    </joint>

    <transmission name="front_right_wheel_trans">
      <type>transmission_interface/SimpleTransmission</type>
      <actuator name="front_right_wheel_motor">
        <mechanicalReduction>1</mechanicalReduction>
      </actuator>
      <joint name="front_right_wheel_joint">
        <hardwareInterface>hardware_interface/VelocityJointInterface</hardwareInterface>
      </joint>
    </transmission>

    <joint name="back_right_wheel_joint" type="continuous">
        <parent link="base_link"/>
        <child link="back_right_wheel"/>
        <origin rpy="1.57 0 0" xyz="-0.18 -0.31 0"/>
        <axis xyz="0 0 -1"/>
    </joint>    
    <transmission name="back_right_wheel_trans">
      <type>transmission_interface/SimpleTransmission</type>
      <actuator name="back_right_wheel_motor">
        <mechanicalReduction>1</mechanicalReduction>
      </actuator>
      <joint name="back_right_wheel_joint">
        <hardwareInterface>hardware_interface/VelocityJointInterface</hardwareInterface>
      </joint>
    </transmission>   

    <joint name="front_left_wheel_joint" type="continuous">
        <parent link="base_link"/>
        <child link="front_left_wheel"/>
        <origin rpy="-1.57 0 0" xyz="0.18 0.31 0"/>
        <axis xyz="0 0 1"/>
    </joint>
    <transmission name="front_left_wheel_trans">
      <type>transmission_interface/SimpleTransmission</type>
      <actuator name="front_left_wheel_motor">
        <mechanicalReduction>1</mechanicalReduction>
      </actuator>
      <joint name="front_left_wheel_joint">
        <hardwareInterface>hardware_interface/VelocityJointInterface</hardwareInterface>
      </joint>
    </transmission>


    <joint name="back_left_wheel_joint" type="continuous">
        <parent link="base_link"/>
        <child link="back_left_wheel"/>
        <origin rpy="-1.57 0 0" xyz="-0.18 0.31 0"/>
        <axis xyz="0 0 1"/>
    </joint>   
    <transmission name="back_left_wheel_trans">
      <type>transmission_interface/SimpleTransmission</type>
      <actuator name="back_left_wheel_motor">
        <mechanicalReduction>1</mechanicalReduction>
      </actuator>
      <joint name="back_left_wheel_joint">
        <hardwareInterface>hardware_interface/VelocityJointInterface</hardwareInterface>
      </joint>
    </transmission>                    

    <gazebo reference="back_right_wheel">
        <mu1 value="200.0"/>
        <mu2 value="100.0"/>
        <kp value="10000000.0" />
        <kd value="1.0" />
        <material>Gazebo/Grey</material>
    </gazebo>
    <gazebo reference="front_right_wheel">
        <mu1 value="200.0"/>
        <mu2 value="100.0"/>
        <kp value="10000000.0" />
        <kd value="1.0" />
        <material>Gazebo/Grey</material>
    </gazebo>
    <gazebo reference="front_left_wheel">
        <mu1 value="200.0"/>
        <mu2 value="100.0"/>
        <kp value="10000000.0" />
        <kd value="1.0" />
        <material>Gazebo/Grey</material>
    </gazebo>
    <gazebo reference="back_left_wheel">
        <mu1 value="200.0"/>
        <mu2 value="100.0"/>
        <kp value="10000000.0" />
        <kd value="1.0" />
        <material>Gazebo/Grey</material>
    </gazebo>


    <gazebo>
		<plugin name="gazebo_ros_control" filename="libgazebo_ros_control.so">
		  <robotNamespace>/</robotNamespace>
		</plugin>
    </gazebo>
</robot>